Workbook

Sheet Capa
I10: ESTADO DE RORAIMA
C11: PREFEITURA MUNICIPAL DE RORAINÓPOLIS
C13: SECRETARIA MUNICIPAL DE EDUCAÇÃO
C15: ESCOLA MUNICIPAL DE ENSINO FUNDAMENTAL PROFESSOR HILDEMAR PEREIRA DE FIGUEREDO
C18: Diário de Classe
C23: Ensino Fundamental - (Anos Iniciais)
C28: Curso/Modalidade: REGULAR
D30: Ano: | F30: 2° | L30: Turma: | N30: D
D32: Turno: | F32: Vespertino | L32: Ano Letivo: | O32: 2026
C35: Professor(a): | G35: ITAMAR VIEIRA NUNES
C38: Componente Curricular: | J38: Educaçao Física
C42: Horário
E43: Aula | H43: Segunda | J43: Terça | L43: Quarta | N43: Quinta | P43: Sexta

Sheet Secret. Escolar
A1: ="Relação Nominal dos Alunos: "&Capa!O32&" " -> Relação Nominal dos Alunos: 2026
A2: ="Ano: "&Capa!F30&" Turma: "&Capa!N30&"" -> Ano: 2° Turma: D
A3: ="Turno: "&Capa!F32&" Professor(a): "&Capa!G35&"" -> Turno: Vespertino Professor(a): ITAMAR VIEIRA NUNES
C4: 1º Bimestre | F4: 2º Bimestre | H4: 3º Bimestre | J4: 4º Bimestre
A5: Nº | B5: NOME DO ALUNO (A) | C5: Movimentações | D5: Total de Falats | E5: Observações | F5: Total de Falats | G5: Observações | H5: Total de Falats | I5: Observações | J5: Total de Falats | K5: Observações
A6: 1 | B6: Adriana Sofia Gonzalez Torres
A7: 2 | B7: Alyson Lucas de Sousa Alencar
A8: 3 | B8: Ana Clara Silva Zanolim
A9: 4 | B9: Antônio Alves Pereira de Souza
A10: 5 | B10: Cecília Resende dos Santos
A11: 6 | B11: Emanuelly Vale da Silva
A12: 7 | B12: Glloria Vitorya Moreira do Vale
A13: 8 | B13: Izabelly Vitória Pereira Muniz
A14: 9 | B14: Kaleu Carneiro Mesquita Tavares
A15: 10 | B15: Lelimar Sofia Reyes Febres
A16: 11 | B16: Luiz Gustavo Rodrigues Carneiro
A17: 12 | B17: Luiz Otávio Santos de Sousa
... A24: 19 | B24: Wuilmer Adrian Ramos Salazar
A25: 20
A26: 21
A27: 22
A28: 23
A29: 24
A30: 25
A31: 26
A32: 27
A33: 28
A34: 29
A35: 30
A36: 31
... A55: 50

Sheet Nome Aluno
A1: ="Ano: "&Capa!F30&" Turma: "&Capa!N30&"" -> Ano: 2° Turma: D | C1: Movimentações
A2: ="Turno: "&Capa!F32&" Ano Letivo: "&Capa!O32 -> Turno: Vespertino Ano Letivo: 2026
A3: =Capa!C28&"" -> Curso/Modalidade: REGULAR
A4: ="Componente Curricular: "&Capa!J38&"" -> Componente Curricular: Educaçao Física
A5: ="Professor(a): "&Capa!G35 -> Professor(a): ITAMAR VIEIRA NUNES
A6: Nº. | B6: Nome do Aluno (a)
A7: 1 | B7: ='Secret. Escolar'!$B$6 -> Adriana Sofia Gonzalez Torres | C7: ='Secret. Escolar'!$C$6
A8: 2 | B8: ='Secret. Escolar'!$B$7 -> Alyson Lucas de Sousa Alencar | C8: ='Secret. Escolar'!$C$7
A9: 3 | B9: ='Secret. Escolar'!$B$8 -> Ana Clara Silva Zanolim | C9: ='Secret. Escolar'!$C$8
A10: 4 | B10: ='Secret. Escolar'!$B$9 -> Antônio Alves Pereira de Souza | C10: ='Secret. Escolar'!$C$9
A11: 5 | B11: ='Secret. Escolar'!$B$10 -> Cecília Resende dos Santos | C11: ='Secret. Escolar'!$C$10
A12: 6 | B12: ='Secret. Escolar'!$B$11 -> Emanuelly Vale da Silva | C12: ='Secret. Escolar'!$C$11
A13: 7 | B13: ='Secret. Escolar'!$B$12 -> Glloria Vitorya Moreira do Vale | C13: ='Secret. Escolar'!$C$12
A14: 8 | B14: ='Secret. Escolar'!$B$13 -> Izabelly Vitória Pereira Muniz | C14: ='Secret. Escolar'!$C$13
A15: 9 | B15: ='Secret. Escolar'!$B$14 -> Kaleu Carneiro Mesquita Tavares | C15: ='Secret. Escolar'!$C$14
A16: 10 | B16: ='Secret. Escolar'!$B$15 -> Lelimar Sofia Reyes Febres | C16: ='Secret. Escolar'!$C$15
A17: 11 | B17: ='Secret. Escolar'!$B$16 -> Luiz Gustavo Rodrigues Carneiro | C17: ='Secret. Escolar'!$C$16
A18: 12 | B18: ='Secret. Escolar'!$B$17 -> Luiz Otávio Santos de Sousa | C18: ='Secret. Escolar'!$C$17
A19: 13 | B19: ='Secret. Escolar'!$B$18 -> Maria Valentina de Souza | C19: ='Secret. Escolar'!$C$18
A20: 14 | B20: ='Secret. Escolar'!$B$19 -> Maysa Barros Caitano dos Santos | C20: ='Secret. Escolar'!$C$19
A21: 15 | B21: ='Secret. Escolar'!$B$20 -> Melissa Oliveira Magalhães | C21: ='Secret. Escolar'!$C$20
A22: 16 | B22: ='Secret. Escolar'!$B$21 -> Neilson de Oliveira Carneiro | C22: ='Secret. Escolar'!$C$21
A23: 17 | B23: ='Secret. Escolar'!$B$22 -> Sarah Gabrielle Coelho Lopes | C23: ='Secret. Escolar'!$C$22
A24: 18 | B24: ='Secret. Escolar'!$B$23 -> Sophia Pereira de Oliveira | C24: ='Secret. Escolar'!$C$23
A25: 19 | B25: ='Secret. Escolar'!$B$24 -> Wuilmer Adrian Ramos Salazar | C25: ='Secret. Escolar'!$C$24
A26: 20 | B26: ='Secret. Escolar'!$B$25 | C26: ='Secret. Escolar'!$C$25
A27: 21 | B27: ='Secret. Escolar'!$B$26 | C27: ='Secret. Escolar'!$C$26
A28: 22 | B28: ='Secret. Escolar'!$B$27 | C28: ='Secret. Escolar'!$C$27
A29: 23 | B29: ='Secret. Escolar'!$B$28 | C29: ='Secret. Escolar'!$C$28
A30: 24 | B30: ='Secret. Escolar'!$B$29 | C30: ='Secret. Escolar'!$C$29
A31: 25 | B31: ='Secret. Escolar'!$B$30 | C31: ='Secret. Escolar'!$C$30
A32: 26 | B32: ='Secret. Escolar'!$B$31 | C32: ='Secret. Escolar'!$C$31
A33: 27 | B33: ='Secret. Escolar'!$B$32 | C33: ='Secret. Escolar'!$C$32
A34: 28 | B34: ='Secret. Escolar'!$B$33 | C34: ='Secret. Escolar'!$C$33
A35: 29 | B35: ='Secret. Escolar'!$B$34 | C35: ='Secret. Escolar'!$C$34
A36: 30 | B36: ='Secret. Escolar'!$B$35 | C36: ='Secret. Escolar'!$C$35
A37: 31 | B37: ='Secret. Escolar'!$B$36 | C37: ='Secret. Escolar'!$C$36
A38: 32 | B38: ='Secret. Escolar'!$B$37 | C38: ='Secret. Escolar'!$C$37
A39: 33 | B39: ='Secret. Escolar'!$B$38 | C39: ='Secret. Escolar'!$C$38
A40: 34 | B40: ='Secret. Escolar'!$B$39 | C40: ='Secret. Escolar'!$C$39
...

Sheet Frequência 1º Bim
A1: ="Componente Curricular: "&Capa!J38&"" -> Componente Curricular: Educaçao Física | D1: ="Ano: "&Capa!F30&" Turma: "&Capa!N30&" Turno: "&Capa!F32&" Ano Letivo: "&Capa!O32&" 1º Bimestre"&" Professor(a): "&Capa!G35 -> Ano: 2° Turma: D Turno: Vespertino Ano Letivo: 2026 1º Bimestre Professor(a): ITAMAR VIEIRA NUNES
A3: Nº ALUNO | B3: ="Aulas Dadas: "&COUNTA(E5:AH5) -> Aulas Dadas: 20 | C3: Movimentções | D3: Registro de Frequência
D4: AULAS DADAS | E4: 1 | F4: 2 | G4: 3 | H4: 4 | I4: 5 | J4: 6 | K4: 7 | L4: 8 | M4: 9 | N4: 10 | O4: 11 | P4: 12 | Q4: 13 | R4: 14 | S4: 15 | T4: 16 | U4: 17 | V4: 18 | W4: 19 | X4: 20 | Y4: 21 | Z4: 22 | AA4: 23 | AB4: 24 | AC4: 25 | AD4: 26 | AE4: 27 | AF4: 28 | AG4: 29 | AH4: 30 | AI4: Total de falta
B5: Nome dos alunos | E5: 46077 | F5: 46079 | G5: 46084 | H5: 46086 | I5: 46091 | J5: 46093 | K5: 46098 | L5: 46100 | M5: 46105 | N5: 46107 | O5: 46112 | P5: 46114 | Q5: 46119 | R5: 46121 | S5: 46126 | T5: 46128 | U5: 46133 | V5: 46135 | W5: 46140 | X5: 46142
A6: 1 | B6: ='Secret. Escolar'!$B$6 -> Adriana Sofia Gonzalez Torres | C6: ='Secret. Escolar'!$C$6 | D6: 1 | E6: . | F6: . | G6: . | H6: . | I6: . | J6: . | K6: . | L6: . | M6: . | N6: . | O6: . | P6: . | Q6: . | R6: . | S6: . | T6: . | U6: . | V6: . | W6: . | X6: . | AI6: =COUNTIF(E6:AH6,"f") -> 0
A7: 2 | B7: ='Secret. Escolar'!$B$7 -> Alyson Lucas de Sousa Alencar | C7: ='Secret. Escolar'!$C$7 | D7: 2 | E7: . | F7: . | G7: . | H7: . | I7: . | J7: . | K7: . | L7: . | M7: . | N7: . | O7: . | P7: . | Q7: . | R7: . | S7: . | T7: . | U7: . | V7: . | W7: . | X7: . | AI7: =COUNTIF(E7:AH7,"f") -> 0
A8: 3 | B8: ='Secret. Escolar'!$B$8 -> Ana Clara Silva Zanolim | C8: ='Secret. Escolar'!$C$8 | D8: 3 | E8: . | F8: . | G8: . | H8: . | I8: . | J8: . | K8: . | L8: . | M8: . | N8: . | O8: . | P8: . | Q8: . | R8: . | S8: . | T8: . | U8: . | V8: . | W8: . | X8: . | AI8: =COUNTIF(E8:AH8,"f") -> 0
A9: 4 | B9: ='Secret. Escolar'!$B$9 -> Antônio Alves Pereira de Souza | C9: ='Secret. Escolar'!$C$9 | D9: 4 | E9: . | F9: . | G9: . | H9: . | I9: . | J9: . | K9: . | L9: . | M9: . | N9: . | O9: . | P9: . | Q9: . | R9: . | S9: . | T9: . | U9: . | V9: . | W9: . | X9: f | AI9: =COUNTIF(E9:AH9,"f") -> 1
A10: 5 | B10: ='Secret. Escolar'!$B$10 -> Cecília Resende dos Santos | C10: ='Secret. Escolar'!$C$10 | D10: 5 | E10: . | F10: . | G10: . | H10: . | I10: . | J10: . | K10: . | L10: . | M10: . | N10: . | O10: . | P10: . | Q10: . | R10: . | S10: . | T10: . | U10: . | V10: . | W10: . | X10: . | AI10: =COUNTIF(E10:AH10,"f") -> 0
A11: 6 | B11: ='Secret. Escolar'!$B$11 -> Emanuelly Vale da Silva | C11: ='Secret. Escolar'!$C$11 | D11: 6 | E11: . | F11: . | G11: . | H11: . | I11: . | J11: . | K11: . | L11: . | M11: . | N11: . | O11: . | P11: . | Q11: . | R11: . | S11: . | T11: . | U11: . | V11: . | W11: . | X11: . | AI11: =COUNTIF(E11:AH11,"f") -> 0
A12: 7 | B12: ='Secret. Escolar'!$B$12 -> Glloria Vitorya Moreira do Vale | C12: ='Secret. Escolar'!$C$12 | D12: 7 | E12: . | F12: . | G12: . | H12: . | I12: . | J12: . | K12: . | L12: . | M12: . | N12: . | O12: . | P12: . | Q12: . | R12: . | S12: . | T12: . | U12: . | V12: . | W12: . | X12: . | AI12: =COUNTIF(E12:AH12,"f") -> 0
A13: 8 | B13: ='Secret. Escolar'!$B$13 -> Izabelly Vitória Pereira Muniz | C13: ='Secret. Escolar'!$C$13 | D13: 8 | E13: . | F13: . | G13: . | H13: . | I13: . | J13: . | K13: . | L13: . | M13: . | N13: . | O13: . | P13: . | Q13: . | R13: . | S13: . | T13: . | U13: . | V13: . | W13: . | X13: f | AI13: =COUNTIF(E13:AH13,"f") -> 1
A14: 9 | B14: ='Secret. Escolar'!$B$14 -> Kaleu Carneiro Mesquita Tavares | C14: ='Secret. Escolar'!$C$14 | D14: 9 | E14: . | F14: . | G14: . | H14: . | I14: . | J14: . | K14: . | L14: . | M14: . | N14: . | O14: . | P14: . | Q14: . | R14: . | S14: . | T14: . | U14: . | V14: . | W14: . | X14: . | AI14: =COUNTIF(E14:AH14,"f") -> 0
A15: 10 | B15: ='Secret. Escolar'!$B$15 -> Lelimar Sofia Reyes Febres | C15: ='Secret. Escolar'!$C$15 | D15: 10 | E15: . | F15: . | G15: . | H15: . | I15: . | J15: . | K15: . | L15: . | M15: . | N15: . | O15: . | P15: . | Q15: . | R15: . | S15: . | T15: . | U15: . | V15: . | W15: . | X15: . | AI15: =COUNTIF(E15:AH15,"f") -> 0
A16: 11 | B16: ='Secret. Escolar'!$B$16 -> Luiz Gustavo Rodrigues Carneiro | C16: ='Secret. Escolar'!$C$16 | D16: 11 | E16: . | F16: . | G16: . | H16: . | I16: . | J16: . | K16: . | L16: . | M16: . | N16: . | O16: . | P16: . | Q16: . | R16: . | S16: . | T16: . | U16: . | V16: . | W16: . | X16: . | AI16: =COUNTIF(E16:AH16,"f") -> 0
A17: 12 | B17: ='Secret. Escolar'!$B$17 -> Luiz Otávio Santos de Sousa | C17: ='Secret. Escolar'!$C$17 | D17: 12 | E17: . | F17: . | G17: . | H17: . | I17: . | J17: . | K17: . | L17: . | M17: . | N17: . | O17: . | P17: . | Q17: . | R17: . | S17: . | T17: . | U17: . | V17: . | W17: . | X17: . | AI17: =COUNTIF(E17:AH17,"f") -> 0
A18: 13 | B18: ='Secret. Escolar'!$B$18 -> Maria Valentina de Souza | C18: ='Secret. Escolar'!$C$18 | D18: 13 | E18: . | F18: . | G18: . | H18: . | I18: . | J18: . | K18: . | L18: . | M18: . | N18: . | O18: . | P18: . | Q18: . | R18: . | S18: . | T18: . | U18: . | V18: . | W18: . | X18: . | AI18: =COUNTIF(E18:AH18,"f") -> 0
A19: 14 | B19: ='Secret. Escolar'!$B$19 -> Maysa Barros Caitano dos Santos | C19: ='Secret. Escolar'!$C$19 | D19: 14 | E19: . | F19: . | G19: . | H19: . | I19: . | J19: . | K19: . | L19: . | M19: . | N19: . | O19: . | P19: . | Q19: . | R19: . | S19: . | T19: . | U19: . | V19: . | W19: . | X19: . | AI19: =COUNTIF(E19:AH19,"f") -> 0
A20: 15 | B20: ='Secret. Escolar'!$B$20 -> Melissa Oliveira Magalhães | C20: ='Secret. Escolar'!$C$20 | D20: 15 | E20: . | F20: . | G20: . | H20: . | I20: . | J20: . | K20: . | L20: . | M20: . | N20: . | O20: . | P20: . | Q20: . | R20: . | S20: . | T20: . | U20: . | V20: . | W20: . | X20: . | AI20: =COUNTIF(E20:AH20,"f") -> 0
A21: 16 | B21: ='Secret. Escolar'!$B$21 -> Neilson de Oliveira Carneiro | C21: ='Secret. Escolar'!$C$21 | D21: 16 | E21: . | F21: . | G21: . | H21: . | I21: . | J21: . | K21: . | L21: . | M21: . | N21: . | O21: . | P21: . | Q21: . | R21: . | S21: . | T21: . | U21: . | V21: . | W21: . | X21: . | AI21: =COUNTIF(E21:AH21,"f") -> 0
A22: 17 | B22: ='Secret. Escolar'!$B$22 -> Sarah Gabrielle Coelho Lopes | C22: ='Secret. Escolar'!$C$22 | D22: 17 | E22: . | F22: . | G22: . | H22: . | I22: . | J22: . | K22: . | L22: . | M22: . | N22: . | O22: . | P22: . | Q22: . | R22: . | S22: . | T22: . | U22: . | V22: . | W22: . | X22: . | AI22: =COUNTIF(E22:AH22,"f") -> 0
A23: 18 | B23: ='Secret. Escolar'!$B$23 -> Sophia Pereira de Oliveira | C23: ='Secret. Escolar'!$C$23 | D23: 18 | E23: . | F23: . | G23: . | H23: . | I23: . | J23: . | K23: . | L23: . | M23: . | N23: . | O23: . | P23: . | Q23: . | R23: . | S23: . | T23: . | U23: . | V23: . | W23: . | X23: . | AI23: =COUNTIF(E23:AH23,"f") -> 0
A24: 19 | B24: ='Secret. Escolar'!$B$24 -> Wuilmer Adrian Ramos Salazar | C24: ='Secret. Escolar'!$C$24 | D24: 19 | E24: . | F24: . | G24: . | H24: . | I24: . | J24: . | K24: . | L24: . | M24: . | N24: . | O24: . | P24: . | Q24: . | R24: . | S24: . | T24: . | U24: . | V24: . | W24: . | X24: . | AI24: =COUNTIF(E24:AH24,"f") -> 0
A25: 20 | B25: ='Secret. Escolar'!$B$25 | C25: ='Secret. Escolar'!$C$25 | D25: 20 | AI25: =COUNTIF(E25:AH25,"f") -> 0
A26: 21 | B26: ='Secret. Escolar'!$B$26 | C26: ='Secret. Escolar'!$C$26 | D26: 21 | AI26: =COUNTIF(E26:AH26,"f") -> 0
A27: 22 | B27: ='Secret. Escolar'!$B$27 | C27: ='Secret. Escolar'!$C$27 | D27: 22 | AI27: =COUNTIF(E27:AH27,"f") -> 0
A28: 23 | B28: ='Secret. Escolar'!$B$28 | C28: ='Secret. Escolar'!$C$28 | D28: 23 | AI28: =COUNTIF(E28:AH28,"f") -> 0
A29: 24 | B29: ='Secret. Escolar'!$B$29 | C29: ='Secret. Escolar'!$C$29 | D29: 24 | AI29: =COUNTIF(E29:AH29,"f") -> 0
A30: 25 | B30: ='Secret. Escolar'!$B$30 | C30: ='Secret. Escolar'!$C$30 | D30: 25 | AI30: =COUNTIF(E30:AH30,"f") -> 0
A31: 26 | B31: ='Secret. Escolar'!$B$31 | C31: ='Secret. Escolar'!$C$31 | D31: 26 | AI31: =COUNTIF(E31:AH31,"f") -> 0
A32: 27 | B32: ='Secret. Escolar'!$B$32 | C32: ='Secret. Escolar'!$C$32 | D32: 27 | AI32: =COUNTIF(E32:AH32,"f") -> 0
A33: 28 | B33: ='Secret. Escolar'!$B$33 | C33: ='Secret. Escolar'!$C$33 | D33: 28 | AI33: =COUNTIF(E33:AH33,"f") -> 0
A34: 29 | B34: ='Secret. Escolar'!$B$34 | C34: ='Secret. Escolar'!$C$34 | D34: 29 | AI34: =COUNTIF(E34:AH34,"f") -> 0
A35: 30 | B35: ='Secret. Escolar'!$B$35 | C35: ='Secret. Escolar'!$C$35 | D35: 30 | AI35: =COUNTIF(E35:AH35,"f") -> 0
A36: 31 | B36: ='Secret. Escolar'!$B$36 | C36: ='Secret. Escolar'!$C$36 | D36: 31 | AI36: =COUNTIF(E36:AH36,"f") -> 0
A37: 32 | B37: ='Secret. Escolar'!$B$37 | C37: ='Secret. Escolar'!$C$37 | D37: 32 | AI37: =COUNTIF(E37:AH37,"f") -> 0
A38: 33 | B38: ='Secret. Escolar'!$B$38 | C38: ='Secret. Escolar'!$C$38 | D38: 33 | AI38: =COUNTIF(E38:AH38,"f") -> 0
A39: 34 | B39: ='Secret. Escolar'!$B$39 | C39: ='Secret. Escolar'!$C$39 | D39: 34 | AI39: =COUNTIF(E39:AH39,"f") -> 0
A40: 35 | B40: ='Secret. Escolar'!$B$40 | C40: ='Secret. Escolar'!$C$40 | D40: 35 | AI40: =COUNTIF(E40:AH40,"f") -> 0
A41: 36 | B41: ='Secret. Escolar'!$B$41 | C41: ='Secret. Escolar'!$C$41 | D41: 36 | AI41: =COUNTIF(E41:AH41,"f") -> 0
...

Sheet Reg. Aulas 1º Bim
B1: DATA | C1: UNIDADE TEMÁTICA | D1: Resumo dos objetos de conhecimentos e metodologias trabalhados
A2: 1 | B2: ='Frequência 1º Bim'!E5 -> 46077
A3: 2 | B3: ='Frequência 1º Bim'!F5 -> 46079
A4: 3 | B4: ='Frequência 1º Bim'!G5 -> 46084
A5: 4 | B5: ='Frequência 1º Bim'!H5 -> 46086
A6: 5 | B6: ='Frequência 1º Bim'!I5 -> 46091
A7: 6 | B7: ='Frequência 1º Bim'!J5 -> 46093
A8: 7 | B8: ='Frequência 1º Bim'!K5 -> 46098
A9: 8 | B9: ='Frequência 1º Bim'!L5 -> 46100
A10: 9 | B10: ='Frequência 1º Bim'!M5 -> 46105
A11: 10 | B11: ='Frequência 1º Bim'!N5 -> 46107
A12: 11 | B12: ='Frequência 1º Bim'!O5 -> 46112
A13: 12 | B13: ='Frequência 1º Bim'!P5 -> 46114
A14: 13 | B14: ='Frequência 1º Bim'!Q5 -> 46119
A15: 14 | B15: ='Frequência 1º Bim'!R5 -> 46121
A16: 15 | B16: ='Frequência 1º Bim'!S5 -> 46126
A17: 16 | B17: ='Frequência 1º Bim'!T5 -> 46128
A18: 17 | B18: ='Frequência 1º Bim'!U5 -> 46133
A19: 18 | B19: ='Frequência 1º Bim'!V5 -> 46135
A20: 19 | B20: ='Frequência 1º Bim'!W5 -> 46140
A21: 20 | B21: ='Frequência 1º Bim'!X5 -> 46142
A22: 21 | B22: ='Frequência 1º Bim'!Y5
A23: 22 | B23: ='Frequência 1º Bim'!Z5
A24: 23 | B24: ='Frequência 1º Bim'!AA5
A25: 24 | B25: ='Frequência 1º Bim'!AB5
A26: 25 | B26: ='Frequência 1º Bim'!AC5
A27: 26 | B27: ='Frequência 1º Bim'!AD5
A28: 27 | B28: ='Frequência 1º Bim'!AE5
A29: 28 | B29: ='Frequência 1º Bim'!AF5
A30: 29 | B30: ='Frequência 1º Bim'!AG5
A31: 30 | B31: ='Frequência 1º Bim'!AH5
A32: Quadro de encerramento do Bimestre
A33: Aulas Previstas | C33: 20
D34: Assinatura do Professor (a)
D35: ="Professor(a): "&Capa!G35 -> Professor(a): ITAMAR VIEIRA NUNES
D36: Data ___/_____/_____
A37: Aulas Dadas | C37: =COUNTA('Frequência 1º Bim'!E5:AH5) -> 20
D38: Carimbo e visto da Autoridade Escolar Encerrado em _______________________

Sheet OBS 1º Bim.
A1: ="Componente Curricular: "&Capa!J38&"" -> Componente Curricular: Educaçao Física | D1: ="Ano: "&Capa!F30&" Turma: "&Capa!N30&" Turno: "&Capa!F32&" Ano Letivo: "&Capa!O32&" 1º Bimestre"&" Professor(a): "&Capa!G35 -> Ano: 2° Turma: D Turno: Vespertino Ano Letivo: 2026 1º Bimestre Professor(a): ITAMAR VIEIRA NUNES
A3: Nº ALUNO | B3: ="Aulas Dadas: "&COUNTA('Frequência 1º Bim'!$E$5:$AH$5) -> Aulas Dadas: 20 | C3: Movimentções | D3: OBSERVAÇÕES DAS FREQUÊNCIAS | E3: OBSERVAÇÕES DOS REGISTROS
B5: Nome dos alunos
A6: 1 | B6: ='Secret. Escolar'!$B$6 -> Adriana Sofia Gonzalez Torres | C6: ='Secret. Escolar'!$C$6
A7: 2 | B7: ='Secret. Escolar'!$B$7 -> Alyson Lucas de Sousa Alencar | C7: ='Secret. Escolar'!$C$7
A8: 3 | B8: ='Secret. Escolar'!$B$8 -> Ana Clara Silva Zanolim | C8: ='Secret. Escolar'!$C$8
A9: 4 | B9: ='Secret. Escolar'!$B$9 -> Antônio Alves Pereira de Souza | C9: ='Secret. Escolar'!$C$9
A10: 5 | B10: ='Secret. Escolar'!$B$10 -> Cecília Resende dos Santos | C10: ='Secret. Escolar'!$C$10
A11: 6 | B11: ='Secret. Escolar'!$B$11 -> Emanuelly Vale da Silva | C11: ='Secret. Escolar'!$C$11
A12: 7 | B12: ='Secret. Escolar'!$B$12 -> Glloria Vitorya Moreira do Vale | C12: ='Secret. Escolar'!$C$12
A13: 8 | B13: ='Secret. Escolar'!$B$13 -> Izabelly Vitória Pereira Muniz | C13: ='Secret. Escolar'!$C$13
A14: 9 | B14: ='Secret. Escolar'!$B$14 -> Kaleu Carneiro Mesquita Tavares | C14: ='Secret. Escolar'!$C$14
A15: 10 | B15: ='Secret. Escolar'!$B$15 -> Lelimar Sofia Reyes Febres | C15: ='Secret. Escolar'!$C$15
A16: 11 | B16: ='Secret. Escolar'!$B$16 -> Luiz Gustavo Rodrigues Carneiro | C16: ='Secret. Escolar'!$C$16
A17: 12 | B17: ='Secret. Escolar'!$B$17 -> Luiz Otávio Santos de Sousa | C17: ='Secret. Escolar'!$C$17
A18: 13 | B18: ='Secret. Escolar'!$B$18 -> Maria Valentina de Souza | C18: ='Secret. Escolar'!$C$18
A19: 14 | B19: ='Secret. Escolar'!$B$19 -> Maysa Barros Caitano dos Santos | C19: ='Secret. Escolar'!$C$19
A20: 15 | B20: ='Secret. Escolar'!$B$20 -> Melissa Oliveira Magalhães | C20: ='Secret. Escolar'!$C$20
A21: 16 | B21: ='Secret. Escolar'!$B$21 -> Neilson de Oliveira Carneiro | C21: ='Secret. Escolar'!$C$21
A22: 17 | B22: ='Secret. Escolar'!$B$22 -> Sarah Gabrielle Coelho Lopes | C22: ='Secret. Escolar'!$C$22
A23: 18 | B23: ='Secret. Escolar'!$B$23 -> Sophia Pereira de Oliveira | C23: ='Secret. Escolar'!$C$23
A24: 19 | B24: ='Secret. Escolar'!$B$24 -> Wuilmer Adrian Ramos Salazar | C24: ='Secret. Escolar'!$C$24
A25: 20 | B25: ='Secret. Escolar'!$B$25 | C25: ='Secret. Escolar'!$C$25
A26: 21 | B26: ='Secret. Escolar'!$B$26 | C26: ='Secret. Escolar'!$C$26
A27: 22 | B27: ='Secret. Escolar'!$B$27 | C27: ='Secret. Escolar'!$C$27
A28: 23 | B28: ='Secret. Escolar'!$B$28 | C28: ='Secret. Escolar'!$C$28
A29: 24 | B29: ='Secret. Escolar'!$B$29 | C29: ='Secret. Escolar'!$C$29
A30: 25 | B30: ='Secret. Escolar'!$B$30 | C30: ='Secret. Escolar'!$C$30
A31: 26 | B31: ='Secret. Escolar'!$B$31 | C31: ='Secret. Escolar'!$C$31
A32: 27 | B32: ='Secret. Escolar'!$B$32 | C32: ='Secret. Escolar'!$C$32
A33: 28 | B33: ='Secret. Escolar'!$B$33 | C33: ='Secret. Escolar'!$C$33
A34: 29 | B34: ='Secret. Escolar'!$B$34 | C34: ='Secret. Escolar'!$C$34
A35: 30 | B35: ='Secret. Escolar'!$B$35 | C35: ='Secret. Escolar'!$C$35
A36: 31 | B36: ='Secret. Escolar'!$B$36 | C36: ='Secret. Escolar'!$C$36
A37: 32 | B37: ='Secret. Escolar'!$B$37 | C37: ='Secret. Escolar'!$C$37
A38: 33 | B38: ='Secret. Escolar'!$B$38 | C38: ='Secret. Escolar'!$C$38
A39: 34 | B39: ='Secret. Escolar'!$B$39 | C39: ='Secret. Escolar'!$C$39
A40: 35 | B40: ='Secret. Escolar'!$B$40 | C40: ='Secret. Escolar'!$C$40
A41: 36 | B41: ='Secret. Escolar'!$B$41 | C41: ='Secret. Escolar'!$C$41
A42: 37 | B42: ='Secret. Escolar'!$B$42 | C42: ='Secret. Escolar'!$C$42
...

Sheet Frequência 2º Bim
A1: ="Componente Curricular: "&Capa!J38&"" -> Componente Curricular: Educaçao Física | D1: ="Ano: "&Capa!F30&" Turma: "&Capa!N30&" Turno: "&Capa!F32&" Ano Letivo: "&Capa!O32&" 2º Bimestre"&" Professor(a): "&Capa!G35 -> Ano: 2° Turma: D Turno: Vespertino Ano Letivo: 2026 2º Bimestre Professor(a): ITAMAR VIEIRA NUNES
A3: Nº ALUNO | B3: ="Aulas Dadas: "&COUNTA(E5:AH5) -> Aulas Dadas: 0 | C3: Movimentções | D3: Registro de Frequência
D4: AULAS DADAS | E4: 1 | F4: 2 | G4: 3 | H4: 4 | I4: 5 | J4: 6 | K4: 7 | L4: 8 | M4: 9 | N4: 10 | O4: 11 | P4: 12 | Q4: 13 | R4: 14 | S4: 15 | T4: 16 | U4: 17 | V4: 18 | W4: 19 | X4: 20 | Y4: 21 | Z4: 22 | AA4: 23 | AB4: 24 | AC4: 25 | AD4: 26 | AE4: 27 | AF4: 28 | AG4: 29 | AH4: 30 | AI4: Total de falta
B5: Nome dos alunos
A6: 1 | B6: ='Secret. Escolar'!$B$6 -> Adriana Sofia Gonzalez Torres | C6: ='Secret. Escolar'!$C$6 | D6: 1 | AI6: =COUNTIF(E6:AH6,"f") -> 0
A7: 2 | B7: ='Secret. Escolar'!$B$7 -> Alyson Lucas de Sousa Alencar | C7: ='Secret. Escolar'!$C$7 | D7: 2 | AI7: =COUNTIF(E7:AH7,"f") -> 0
A8: 3 | B8: ='Secret. Escolar'!$B$8 -> Ana Clara Silva Zanolim | C8: ='Secret. Escolar'!$C$8 | D8: 3 | AI8: =COUNTIF(E8:AH8,"f") -> 0
A9: 4 | B9: ='Secret. Escolar'!$B$9 -> Antônio Alves Pereira de Souza | C9: ='Secret. Escolar'!$C$9 | D9: 4 | AI9: =COUNTIF(E9:AH9,"f") -> 0
A10: 5 | B10: ='Secret. Escolar'!$B$10 -> Cecília Resende dos Santos | C10: ='Secret. Escolar'!$C$10 | D10: 5 | AI10: =COUNTIF(E10:AH10,"f") -> 0
A11: 6 | B11: ='Secret. Escolar'!$B$11 -> Emanuelly Vale da Silva | C11: ='Secret. Escolar'!$C$11 | D11: 6 | AI11: =COUNTIF(E11:AH11,"f") -> 0
A12: 7 | B12: ='Secret. Escolar'!$B$12 -> Glloria Vitorya Moreira do Vale | C12: ='Secret. Escolar'!$C$12 | D12: 7 | AI12: =COUNTIF(E12:AH12,"f") -> 0
A13: 8 | B13: ='Secret. Escolar'!$B$13 -> Izabelly Vitória Pereira Muniz | C13: ='Secret. Escolar'!$C$13 | D13: 8 | AI13: =COUNTIF(E13:AH13,"f") -> 0
A14: 9 | B14: ='Secret. Escolar'!$B$14 -> Kaleu Carneiro Mesquita Tavares | C14: ='Secret. Escolar'!$C$14 | D14: 9 | AI14: =COUNTIF(E14:AH14,"f") -> 0
A15: 10 | B15: ='Secret. Escolar'!$B$15 -> Lelimar Sofia Reyes Febres | C15: ='Secret. Escolar'!$C$15 | D15: 10 | AI15: =COUNTIF(E15:AH15,"f") -> 0
A16: 11 | B16: ='Secret. Escolar'!$B$16 -> Luiz Gustavo Rodrigues Carneiro | C16: ='Secret. Escolar'!$C$16 | D16: 11 | AI16: =COUNTIF(E16:AH16,"f") -> 0
A17: 12 | B17: ='Secret. Escolar'!$B$17 -> Luiz Otávio Santos de Sousa | C17: ='Secret. Escolar'!$C$17 | D17: 12 | AI17: =COUNTIF(E17:AH17,"f") -> 0
A18: 13 | B18: ='Secret. Escolar'!$B$18 -> Maria Valentina de Souza | C18: ='Secret. Escolar'!$C$18 | D18: 13 | AI18: =COUNTIF(E18:AH18,"f") -> 0
A19: 14 | B19: ='Secret. Escolar'!$B$19 -> Maysa Barros Caitano dos Santos | C19: ='Secret. Escolar'!$C$19 | D19: 14 | AI19: =COUNTIF(E19:AH19,"f") -> 0
A20: 15 | B20: ='Secret. Escolar'!$B$20 -> Melissa Oliveira Magalhães | C20: ='Secret. Escolar'!$C$20 | D20: 15 | AI20: =COUNTIF(E20:AH20,"f") -> 0
A21: 16 | B21: ='Secret. Escolar'!$B$21 -> Neilson de Oliveira Carneiro | C21: ='Secret. Escolar'!$C$21 | D21: 16 | AI21: =COUNTIF(E21:AH21,"f") -> 0
A22: 17 | B22: ='Secret. Escolar'!$B$22 -> Sarah Gabrielle Coelho Lopes | C22: ='Secret. Escolar'!$C$22 | D22: 17 | AI22: =COUNTIF(E22:AH22,"f") -> 0
A23: 18 | B23: ='Secret. Escolar'!$B$23 -> Sophia Pereira de Oliveira | C23: ='Secret. Escolar'!$C$23 | D23: 18 | AI23: =COUNTIF(E23:AH23,"f") -> 0
A24: 19 | B24: ='Secret. Escolar'!$B$24 -> Wuilmer Adrian Ramos Salazar | C24: ='Secret. Escolar'!$C$24 | D24: 19 | AI24: =COUNTIF(E24:AH24,"f") -> 0
A25: 20 | B25: ='Secret. Escolar'!$B$25 | C25: ='Secret. Escolar'!$C$25 | D25: 20 | AI25: =COUNTIF(E25:AH25,"f") -> 0
A26: 21 | B26: ='Secret. Escolar'!$B$26 | C26: ='Secret. Escolar'!$C$26 | D26: 21 | AI26: =COUNTIF(E26:AH26,"f") -> 0
A27: 22 | B27: ='Secret. Escolar'!$B$27 | C27: ='Secret. Escolar'!$C$27 | D27: 22 | AI27: =COUNTIF(E27:AH27,"f") -> 0
A28: 23 | B28: ='Secret. Escolar'!$B$28 | C28: ='Secret. Escolar'!$C$28 | D28: 23 | AI28: =COUNTIF(E28:AH28,"f") -> 0
A29: 24 | B29: ='Secret. Escolar'!$B$29 | C29: ='Secret. Escolar'!$C$29 | D29: 24 | AI29: =COUNTIF(E29:AH29,"f") -> 0
A30: 25 | B30: ='Secret. Escolar'!$B$30 | C30: ='Secret. Escolar'!$C$30 | D30: 25 | AI30: =COUNTIF(E30:AH30,"f") -> 0
A31: 26 | B31: ='Secret. Escolar'!$B$31 | C31: ='Secret. Escolar'!$C$31 | D31: 26 | AI31: =COUNTIF(E31:AH31,"f") -> 0
A32: 27 | B32: ='Secret. Escolar'!$B$32 | C32: ='Secret. Escolar'!$C$32 | D32: 27 | AI32: =COUNTIF(E32:AH32,"f") -> 0
A33: 28 | B33: ='Secret. Escolar'!$B$33 | C33: ='Secret. Escolar'!$C$33 | D33: 28 | AI33: =COUNTIF(E33:AH33,"f") -> 0
A34: 29 | B34: ='Secret. Escolar'!$B$34 | C34: ='Secret. Escolar'!$C$34 | D34: 29 | AI34: =COUNTIF(E34:AH34,"f") -> 0
A35: 30 | B35: ='Secret. Escolar'!$B$35 | C35: ='Secret. Escolar'!$C$35 | D35: 30 | AI35: =COUNTIF(E35:AH35,"f") -> 0
A36: 31 | B36: ='Secret. Escolar'!$B$36 | C36: ='Secret. Escolar'!$C$36 | D36: 31 | AI36: =COUNTIF(E36:AH36,"f") -> 0
A37: 32 | B37: ='Secret. Escolar'!$B$37 | C37: ='Secret. Escolar'!$C$37 | D37: 32 | AI37: =COUNTIF(E37:AH37,"f") -> 0
A38: 33 | B38: ='Secret. Escolar'!$B$38 | C38: ='Secret. Escolar'!$C$38 | D38: 33 | AI38: =COUNTIF(E38:AH38,"f") -> 0
A39: 34 | B39: ='Secret. Escolar'!$B$39 | C39: ='Secret. Escolar'!$C$39 | D39: 34 | AI39: =COUNTIF(E39:AH39,"f") -> 0
A40: 35 | B40: ='Secret. Escolar'!$B$40 | C40: ='Secret. Escolar'!$C$40 | D40: 35 | AI40: =COUNTIF(E40:AH40,"f") -> 0
A41: 36 | B41: ='Secret. Escolar'!$B$41 | C41: ='Secret. Escolar'!$C$41 | D41: 36 | AI41: =COUNTIF(E41:AH41,"f") -> 0
...

Sheet Reg. Aulas 2º Bim
A1: AULAS DADAS | B1: DATA | C1: UNIDADE TEMÁTICA | D1: Resumo dos objetos de conhecimentos e metodologias trabalhados
A2: 1 | B2: ='Frequência 2º Bim'!E5
A3: 2 | B3: ='Frequência 2º Bim'!F5
A4: 3 | B4: ='Frequência 2º Bim'!G5
A5: 4 | B5: ='Frequência 2º Bim'!H5
A6: 5 | B6: ='Frequência 2º Bim'!I5
A7: 6 | B7: ='Frequência 2º Bim'!J5
A8: 7 | B8: ='Frequência 2º Bim'!K5
A9: 8 | B9: ='Frequência 2º Bim'!L5
A10: 9 | B10: ='Frequência 2º Bim'!M5
A11: 10 | B11: ='Frequência 2º Bim'!N5
A12: 11 | B12: ='Frequência 2º Bim'!O5
A13: 12 | B13: ='Frequência 2º Bim'!P5
A14: 13 | B14: ='Frequência 2º Bim'!Q5
A15: 14 | B15: ='Frequência 2º Bim'!R5
A16: 15 | B16: ='Frequência 2º Bim'!S5
A17: 16 | B17: ='Frequência 2º Bim'!T5
A18: 17 | B18: ='Frequência 2º Bim'!U5
A19: 18 | B19: ='Frequência 2º Bim'!V5
A20: 19 | B20: ='Frequência 2º Bim'!W5
A21: 20 | B21: ='Frequência 2º Bim'!X5
A22: 21 | B22: ='Frequência 2º Bim'!Y5
A23: 22 | B23: ='Frequência 2º Bim'!Z5
A24: 23 | B24: ='Frequência 2º Bim'!AA5
A25: 24 | B25: ='Frequência 2º Bim'!AB5
A26: 25 | B26: ='Frequência 2º Bim'!AC5
A27: 26 | B27: ='Frequência 2º Bim'!AD5
A28: 27 | B28: ='Frequência 2º Bim'!AE5
A29: 28 | B29: ='Frequência 2º Bim'!AF5
A30: 29 | B30: ='Frequência 2º Bim'!AG5
A31: 30 | B31: ='Frequência 2º Bim'!AH5
A32: Quadro de encerramento do Bimestre
A33: Aulas Previstas | C33: 20
D34: Assinatura do Professor (a)
D35: ="Professor(a): "&Capa!G35 -> Professor(a): ITAMAR VIEIRA NUNES
D36: Data ___/_____/_____
A37: Aulas Dadas | C37: =COUNTA('Frequência 2º Bim'!E5:AH5) -> 0
D38: Carimbo e visto da Autoridade Escolar Encerrado em _______________________

Sheet OBS 2º Bim.
A1: ="Componente Curricular: "&Capa!J38&"" -> Componente Curricular: Educaçao Física | D1: ="Ano: "&Capa!F30&" Turma: "&Capa!N30&" Turno: "&Capa!F32&" Ano Letivo: "&Capa!O32&" 2º Bimestre"&" Professor(a): "&Capa!G35 -> Ano: 2° Turma: D Turno: Vespertino Ano Letivo: 2026 2º Bimestre Professor(a): ITAMAR VIEIRA NUNES
A3: Nº ALUNO | B3: ="Aulas Dadas: "&COUNTA('Frequência 2º Bim'!$E$5:$AH$5) -> Aulas Dadas: 0 | C3: Movimentções | D3: OBSERVAÇÕES DAS FREQUÊNCIAS | E3: OBSERVAÇÕES DOS REGISTROS
B5: Nome dos alunos
A6: 1 | B6: ='Secret. Escolar'!$B$6 -> Adriana Sofia Gonzalez Torres | C6: ='Secret. Escolar'!$C$6
A7: 2 | B7: ='Secret. Escolar'!$B$7 -> Alyson Lucas de Sousa Alencar | C7: ='Secret. Escolar'!$C$7
A8: 3 | B8: ='Secret. Escolar'!$B$8 -> Ana Clara Silva Zanolim | C8: ='Secret. Escolar'!$C$8
A9: 4 | B9: ='Secret. Escolar'!$B$9 -> Antônio Alves Pereira de Souza | C9: ='Secret. Escolar'!$C$9
A10: 5 | B10: ='Secret. Escolar'!$B$10 -> Cecília Resende dos Santos | C10: ='Secret. Escolar'!$C$10
A11: 6 | B11: ='Secret. Escolar'!$B$11 -> Emanuelly Vale da Silva | C11: ='Secret. Escolar'!$C$11
A12: 7 | B12: ='Secret. Escolar'!$B$12 -> Glloria Vitorya Moreira do Vale | C12: ='Secret. Escolar'!$C$12
A13: 8 | B13: ='Secret. Escolar'!$B$13 -> Izabelly Vitória Pereira Muniz | C13: ='Secret. Escolar'!$C$13
A14: 9 | B14: ='Secret. Escolar'!$B$14 -> Kaleu Carneiro Mesquita Tavares | C14: ='Secret. Escolar'!$C$14
A15: 10 | B15: ='Secret. Escolar'!$B$15 -> Lelimar Sofia Reyes Febres | C15: ='Secret. Escolar'!$C$15
A16: 11 | B16: ='Secret. Escolar'!$B$16 -> Luiz Gustavo Rodrigues Carneiro | C16: ='Secret. Escolar'!$C$16
A17: 12 | B17: ='Secret. Escolar'!$B$17 -> Luiz Otávio Santos de Sousa | C17: ='Secret. Escolar'!$C$17
A18: 13 | B18: ='Secret. Escolar'!$B$18 -> Maria Valentina de Souza | C18: ='Secret. Escolar'!$C$18
A19: 14 | B19: ='Secret. Escolar'!$B$19 -> Maysa Barros Caitano dos Santos | C19: ='Secret. Escolar'!$C$19
A20: 15 | B20: ='Secret. Escolar'!$B$20 -> Melissa Oliveira Magalhães | C20: ='Secret. Escolar'!$C$20
A21: 16 | B21: ='Secret. Escolar'!$B$21 -> Neilson de Oliveira Carneiro | C21: ='Secret. Escolar'!$C$21
A22: 17 | B22: ='Secret. Escolar'!$B$22 -> Sarah Gabrielle Coelho Lopes | C22: ='Secret. Escolar'!$C$22
A23: 18 | B23: ='Secret. Escolar'!$B$23 -> Sophia Pereira de Oliveira | C23: ='Secret. Escolar'!$C$23
A24: 19 | B24: ='Secret. Escolar'!$B$24 -> Wuilmer Adrian Ramos Salazar | C24: ='Secret. Escolar'!$C$24
A25: 20 | B25: ='Secret. Escolar'!$B$25 | C25: ='Secret. Escolar'!$C$25
A26: 21 | B26: ='Secret. Escolar'!$B$26 | C26: ='Secret. Escolar'!$C$26
A27: 22 | B27: ='Secret. Escolar'!$B$27 | C27: ='Secret. Escolar'!$C$27
A28: 23 | B28: ='Secret. Escolar'!$B$28 | C28: ='Secret. Escolar'!$C$28
A29: 24 | B29: ='Secret. Escolar'!$B$29 | C29: ='Secret. Escolar'!$C$29
A30: 25 | B30: ='Secret. Escolar'!$B$30 | C30: ='Secret. Escolar'!$C$30
A31: 26 | B31: ='Secret. Escolar'!$B$31 | C31: ='Secret. Escolar'!$C$31
A32: 27 | B32: ='Secret. Escolar'!$B$32 | C32: ='Secret. Escolar'!$C$32
A33: 28 | B33: ='Secret. Escolar'!$B$33 | C33: ='Secret. Escolar'!$C$33
A34: 29 | B34: ='Secret. Escolar'!$B$34 | C34: ='Secret. Escolar'!$C$34
A35: 30 | B35: ='Secret. Escolar'!$B$35 | C35: ='Secret. Escolar'!$C$35
A36: 31 | B36: ='Secret. Escolar'!$B$36 | C36: ='Secret. Escolar'!$C$36
A37: 32 | B37: ='Secret. Escolar'!$B$37 | C37: ='Secret. Escolar'!$C$37
A38: 33 | B38: ='Secret. Escolar'!$B$38 | C38: ='Secret. Escolar'!$C$38
A39: 34 | B39: ='Secret. Escolar'!$B$39 | C39: ='Secret. Escolar'!$C$39
A40: 35 | B40: ='Secret. Escolar'!$B$40 | C40: ='Secret. Escolar'!$C$40
A41: 36 | B41: ='Secret. Escolar'!$B$41 | C41: ='Secret. Escolar'!$C$41
A42: 37 | B42: ='Secret. Escolar'!$B$42 | C42: ='Secret. Escolar'!$C$42
...

Sheet Acompanhamento 1º Semestre.
A1: =Capa!$C$38&Capa!K38&" 1° Semestre" -> Componente Curricular: 1° Semestre | D1: ="Ano: "&Capa!F30&" Turma: "&Capa!N30&" Turno: "&Capa!F32&" Ano Letivo: "&Capa!O32&" " -> Ano: 2° Turma: D Turno: Vespertino Ano Letivo: 2026
D2: ="Professor(a): "&Capa!G35 -> Professor(a): ITAMAR VIEIRA NUNES
A3: RESERVADO AO PROFESSOR (A) DE EDUCAÇÃO FÍSICA | D3: Acompanhamento do desenvolvimentos físico do aluno
A4: Nº do Aluno | B4: Nome dos alunos | C4: Movimentções | D4: Data do acompanhamento | E4: Sexo | F4: Idade | G4: Peso | H4: Estatura | I4: IMC | J4: Situação
A5: 1 | B5: ='Secret. Escolar'!$B$6 -> Adriana Sofia Gonzalez Torres | C5: ='Secret. Escolar'!$C$6 | I5: =IFERROR(G5/(H5*H5), "") | J5: {=IFERROR(IF(I5 < INDEX('Referência'!$B$2:$B$21, MATCH(F5&E5, 'Referência'!$A$2:$A$21, 0)), "Abaixo do peso", IF(I5 < INDEX('Referência'!$C$2:$C$21, MATCH(F5&E5, 'Referência'!$A$2:$A$21, 0)), "Normal", IF(I5 < INDEX('Referência'!$D$2:$D$21, MATCH(F5&E5, 'Referência'!$A$2:$A$21, 0)), "Sobrepeso", "Obesidade"))), "")}
A6: 2 | B6: ='Secret. Escolar'!$B$7 -> Alyson Lucas de Sousa Alencar | C6: ='Secret. Escolar'!$C$7 | I6: =IFERROR(G6/(H6*H6), "") | J6: {=IFERROR(IF(I6 < INDEX('Referência'!$B$2:$B$21, MATCH(F6&E6, 'Referência'!$A$2:$A$21, 0)), "Abaixo do peso", IF(I6 < INDEX('Referência'!$C$2:$C$21, MATCH(F6&E6, 'Referência'!$A$2:$A$21, 0)), "Normal", IF(I6 < INDEX('Referência'!$D$2:$D$21, MATCH(F6&E6, 'Referência'!$A$2:$A$21, 0)), "Sobrepeso", "Obesidade"))), "")}
A7: 3 | B7: ='Secret. Escolar'!$B$8 -> Ana Clara Silva Zanolim | C7: ='Secret. Escolar'!$C$8 | I7: =IFERROR(G7/(H7*H7), "") | J7: {=IFERROR(IF(I7 < INDEX('Referência'!$B$2:$B$21, MATCH(F7&E7, 'Referência'!$A$2:$A$21, 0)), "Abaixo do peso", IF(I7 < INDEX('Referência'!$C$2:$C$21, MATCH(F7&E7, 'Referência'!$A$2:$A$21, 0)), "Normal", IF(I7 < INDEX('Referência'!$D$2:$D$21, MATCH(F7&E7, 'Referência'!$A$2:$A$21, 0)), "Sobrepeso", "Obesidade"))), "")}
A8: 4 | B8: ='Secret. Escolar'!$B$9 -> Antônio Alves Pereira de Souza | C8: ='Secret. Escolar'!$C$9 | I8: =IFERROR(G8/(H8*H8), "") | J8: {=IFERROR(IF(I8 < INDEX('Referência'!$B$2:$B$21, MATCH(F8&E8, 'Referência'!$A$2:$A$21, 0)), "Abaixo do peso", IF(I8 < INDEX('Referência'!$C$2:$C$21, MATCH(F8&E8, 'Referência'!$A$2:$A$21, 0)), "Normal", IF(I8 < INDEX('Referência'!$D$2:$D$21, MATCH(F8&E8, 'Referência'!$A$2:$A$21, 0)), "Sobrepeso", "Obesidade"))), "")}
A9: 5 | B9: ='Secret. Escolar'!$B$10 -> Cecília Resende dos Santos | C9: ='Secret. Escolar'!$C$10 | I9: =IFERROR(G9/(H9*H9), "") | J9: {=IFERROR(IF(I9 < INDEX('Referência'!$B$2:$B$21, MATCH(F9&E9, 'Referência'!$A$2:$A$21, 0)), "Abaixo do peso", IF(I9 < INDEX('Referência'!$C$2:$C$21, MATCH(F9&E9, 'Referência'!$A$2:$A$21, 0)), "Normal", IF(I9 < INDEX('Referência'!$D$2:$D$21, MATCH(F9&E9, 'Referência'!$A$2:$A$21, 0)), "Sobrepeso", "Obesidade"))), "")}
A10: 6 | B10: ='Secret. Escolar'!$B$11 -> Emanuelly Vale da Silva | C10: ='Secret. Escolar'!$C$11 | I10: =IFERROR(G10/(H10*H10), "") | J10: {=IFERROR(IF(I10 < INDEX('Referência'!$B$2:$B$21, MATCH(F10&E10, 'Referência'!$A$2:$A$21, 0)), "Abaixo do peso", IF(I10 < INDEX('Referência'!$C$2:$C$21, MATCH(F10&E10, 'Referência'!$A$2:$A$21, 0)), "Normal", IF(I10 < INDEX('Referência'!$D$2:$D$21, MATCH(F10&E10, 'Referência'!$A$2:$A$21, 0)), "Sobrepeso", "Obesidade"))), "")}
A11: 7 | B11: ='Secret. Escolar'!$B$12 -> Glloria Vitorya Moreira do Vale | C11: ='Secret. Escolar'!$C$12 | I11: =IFERROR(G11/(H11*H11), "") | J11: {=IFERROR(IF(I11 < INDEX('Referência'!$B$2:$B$21, MATCH(F11&E11, 'Referência'!$A$2:$A$21, 0)), "Abaixo do peso", IF(I11 < INDEX('Referência'!$C$2:$C$21, MATCH(F11&E11, 'Referência'!$A$2:$A$21, 0)), "Normal", IF(I11 < INDEX('Referência'!$D$2:$D$21, MATCH(F11&E11, 'Referência'!$A$2:$A$21, 0)), "Sobrepeso", "Obesidade"))), "")}
A12: 8 | B12: ='Secret. Escolar'!$B$13 -> Izabelly Vitória Pereira Muniz | C12: ='Secret. Escolar'!$C$13 | I12: =IFERROR(G12/(H12*H12), "") | J12: {=IFERROR(IF(I12 < INDEX('Referência'!$B$2:$B$21, MATCH(F12&E12, 'Referência'!$A$2:$A$21, 0)), "Abaixo do peso", IF(I12 < INDEX('Referência'!$C$2:$C$21, MATCH(F12&E12, 'Referência'!$A$2:$A$21, 0)), "Normal", IF(I12 < INDEX('Referência'!$D$2:$D$21, MATCH(F12&E12, 'Referência'!$A$2:$A$21, 0)), "Sobrepeso", "Obesidade"))), "")}
A13: 9 | B13: ='Secret. Escolar'!$B$14 -> Kaleu Carneiro Mesquita Tavares | C13: ='Secret. Escolar'!$C$14 | I13: =IFERROR(G13/(H13*H13), "") | J13: {=IFERROR(IF(I13 < INDEX('Referência'!$B$2:$B$21, MATCH(F13&E13, 'Referência'!$A$2:$A$21, 0)), "Abaixo do peso", IF(I13 < INDEX('Referência'!$C$2:$C$21, MATCH(F13&E13, 'Referência'!$A$2:$A$21, 0)), "Normal", IF(I13 < INDEX('Referência'!$D$2:$D$21, MATCH(F13&E13, 'Referência'!$A$2:$A$21, 0)), "Sobrepeso", "Obesidade"))), "")}
A14: 10 | B14: ='Secret. Escolar'!$B$15 -> Lelimar Sofia Reyes Febres | C14: ='Secret. Escolar'!$C$15 | I14: =IFERROR(G14/(H14*H14), "") | J14: {=IFERROR(IF(I14 < INDEX('Referência'!$B$2:$B$21, MATCH(F14&E14, 'Referência'!$A$2:$A$21, 0)), "Abaixo do peso", IF(I14 < INDEX('Referência'!$C$2:$C$21, MATCH(F14&E14, 'Referência'!$A$2:$A$21, 0)), "Normal", IF(I14 < INDEX('Referência'!$D$2:$D$21, MATCH(F14&E14, 'Referência'!$A$2:$A$21, 0)), "Sobrepeso", "Obesidade"))), "")}
A15: 11 | B15: ='Secret. Escolar'!$B$16 -> Luiz Gustavo Rodrigues Carneiro | C15: ='Secret. Escolar'!$C$16 | I15: =IFERROR(G15/(H15*H15), "") | J15: {=IFERROR(IF(I15 < INDEX('Referência'!$B$2:$B$21, MATCH(F15&E15, 'Referência'!$A$2:$A$21, 0)), "Abaixo do peso", IF(I15 < INDEX('Referência'!$C$2:$C$21, MATCH(F15&E15, 'Referência'!$A$2:$A$21, 0)), "Normal", IF(I15 < INDEX('Referência'!$D$2:$D$21, MATCH(F15&E15, 'Referência'!$A$2:$A$21, 0)), "Sobrepeso", "Obesidade"))), "")}
A16: 12 | B16: ='Secret. Escolar'!$B$17 -> Luiz Otávio Santos de Sousa | C16: ='Secret. Escolar'!$C$17 | I16: =IFERROR(G16/(H16*H16), "") | J16: {=IFERROR(IF(I16 < INDEX('Referência'!$B$2:$B$21, MATCH(F16&E16, 'Referência'!$A$2:$A$21, 0)), "Abaixo do peso", IF(I16 < INDEX('Referência'!$C$2:$C$21, MATCH(F16&E16, 'Referência'!$A$2:$A$21, 0)), "Normal", IF(I16 < INDEX('Referência'!$D$2:$D$21, MATCH(F16&E16, 'Referência'!$A$2:$A$21, 0)), "Sobrepeso", "Obesidade"))), "")}
A17: 13 | B17: ='Secret. Escolar'!$B$18 -> Maria Valentina de Souza | C17: ='Secret. Escolar'!$C$18 | I17: =IFERROR(G17/(H17*H17), "") | J17: {=IFERROR(IF(I17 < INDEX('Referência'!$B$2:$B$21, MATCH(F17&E17, 'Referência'!$A$2:$A$21, 0)), "Abaixo do peso", IF(I17 < INDEX('Referência'!$C$2:$C$21, MATCH(F17&E17, 'Referência'!$A$2:$A$21, 0)), "Normal", IF(I17 < INDEX('Referência'!$D$2:$D$21, MATCH(F17&E17, 'Referência'!$A$2:$A$21, 0)), "Sobrepeso", "Obesidade"))), "")}
A18: 14 | B18: ='Secret. Escolar'!$B$19 -> Maysa Barros Caitano dos Santos | C18: ='Secret. Escolar'!$C$19 | I18: =IFERROR(G18/(H18*H18), "") | J18: {=IFERROR(IF(I18 < INDEX('Referência'!$B$2:$B$21, MATCH(F18&E18, 'Referência'!$A$2:$A$21, 0)), "Abaixo do peso", IF(I18 < INDEX('Referência'!$C$2:$C$21, MATCH(F18&E18, 'Referência'!$A$2:$A$21, 0)), "Normal", IF(I18 < INDEX('Referência'!$D$2:$D$21, MATCH(F18&E18, 'Referência'!$A$2:$A$21, 0)), "Sobrepeso", "Obesidade"))), "")}
A19: 15 | B19: ='Secret. Escolar'!$B$20 -> Melissa Oliveira Magalhães | C19: ='Secret. Escolar'!$C$20 | I19: =IFERROR(G19/(H19*H19), "") | J19: {=IFERROR(IF(I19 < INDEX('Referência'!$B$2:$B$21, MATCH(F19&E19, 'Referência'!$A$2:$A$21, 0)), "Abaixo do peso", IF(I19 < INDEX('Referência'!$C$2:$C$21, MATCH(F19&E19, 'Referência'!$A$2:$A$21, 0)), "Normal", IF(I19 < INDEX('Referência'!$D$2:$D$21, MATCH(F19&E19, 'Referência'!$A$2:$A$21, 0)), "Sobrepeso", "Obesidade"))), "")}
A20: 16 | B20: ='Secret. Escolar'!$B$21 -> Neilson de Oliveira Carneiro | C20: ='Secret. Escolar'!$C$21 | I20: =IFERROR(G20/(H20*H20), "") | J20: {=IFERROR(IF(I20 < INDEX('Referência'!$B$2:$B$21, MATCH(F20&E20, 'Referência'!$A$2:$A$21, 0)), "Abaixo do peso", IF(I20 < INDEX('Referência'!$C$2:$C$21, MATCH(F20&E20, 'Referência'!$A$2:$A$21, 0)), "Normal", IF(I20 < INDEX('Referência'!$D$2:$D$21, MATCH(F20&E20, 'Referência'!$A$2:$A$21, 0)), "Sobrepeso", "Obesidade"))), "")}
A21: 17 | B21: ='Secret. Escolar'!$B$22 -> Sarah Gabrielle Coelho Lopes | C21: ='Secret. Escolar'!$C$22 | I21: =IFERROR(G21/(H21*H21), "") | J21: {=IFERROR(IF(I21 < INDEX('Referência'!$B$2:$B$21, MATCH(F21&E21, 'Referência'!$A$2:$A$21, 0)), "Abaixo do peso", IF(I21 < INDEX('Referência'!$C$2:$C$21, MATCH(F21&E21, 'Referência'!$A$2:$A$21, 0)), "Normal", IF(I21 < INDEX('Referência'!$D$2:$D$21, MATCH(F21&E21, 'Referência'!$A$2:$A$21, 0)), "Sobrepeso", "Obesidade"))), "")}
A22: 18 | B22: ='Secret. Escolar'!$B$23 -> Sophia Pereira de Oliveira | C22: ='Secret. Escolar'!$C$23 | I22: =IFERROR(G22/(H22*H22), "") | J22: {=IFERROR(IF(I22 < INDEX('Referência'!$B$2:$B$21, MATCH(F22&E22, 'Referência'!$A$2:$A$21, 0)), "Abaixo do peso", IF(I22 < INDEX('Referência'!$C$2:$C$21, MATCH(F22&E22, 'Referência'!$A$2:$A$21, 0)), "Normal", IF(I22 < INDEX('Referência'!$D$2:$D$21, MATCH(F22&E22, 'Referência'!$A$2:$A$21, 0)), "Sobrepeso", "Obesidade"))), "")}
A23: 19 | B23: ='Secret. Escolar'!$B$24 -> Wuilmer Adrian Ramos Salazar | C23: ='Secret. Escolar'!$C$24 | I23: =IFERROR(G23/(H23*H23), "") | J23: {=IFERROR(IF(I23 < INDEX('Referência'!$B$2:$B$21, MATCH(F23&E23, 'Referência'!$A$2:$A$21, 0)), "Abaixo do peso", IF(I23 < INDEX('Referência'!$C$2:$C$21, MATCH(F23&E23, 'Referência'!$A$2:$A$21, 0)), "Normal", IF(I23 < INDEX('Referência'!$D$2:$D$21, MATCH(F23&E23, 'Referência'!$A$2:$A$21, 0)), "Sobrepeso", "Obesidade"))), "")}
A24: 20 | B24: ='Secret. Escolar'!$B$25 | C24: ='Secret. Escolar'!$C$25 | I24: =IFERROR(G24/(H24*H24), "") | J24: {=IFERROR(IF(I24 < INDEX('Referência'!$B$2:$B$21, MATCH(F24&E24, 'Referência'!$A$2:$A$21, 0)), "Abaixo do peso", IF(I24 < INDEX('Referência'!$C$2:$C$21, MATCH(F24&E24, 'Referência'!$A$2:$A$21, 0)), "Normal", IF(I24 < INDEX('Referência'!$D$2:$D$21, MATCH(F24&E24, 'Referência'!$A$2:$A$21, 0)), "Sobrepeso", "Obesidade"))), "")}
A25: 21 | B25: ='Secret. Escolar'!$B$26 | C25: ='Secret. Escolar'!$C$26 | I25: =IFERROR(G25/(H25*H25), "") | J25: {=IFERROR(IF(I25 < INDEX('Referência'!$B$2:$B$21, MATCH(F25&E25, 'Referência'!$A$2:$A$21, 0)), "Abaixo do peso", IF(I25 < INDEX('Referência'!$C$2:$C$21, MATCH(F25&E25, 'Referência'!$A$2:$A$21, 0)), "Normal", IF(I25 < INDEX('Referência'!$D$2:$D$21, MATCH(F25&E25, 'Referência'!$A$2:$A$21, 0)), "Sobrepeso", "Obesidade"))), "")}
A26: 22 | B26: ='Secret. Escolar'!$B$27 | C26: ='Secret. Escolar'!$C$27 | I26: =IFERROR(G26/(H26*H26), "") | J26: {=IFERROR(IF(I26 < INDEX('Referência'!$B$2:$B$21, MATCH(F26&E26, 'Referência'!$A$2:$A$21, 0)), "Abaixo do peso", IF(I26 < INDEX('Referência'!$C$2:$C$21, MATCH(F26&E26, 'Referência'!$A$2:$A$21, 0)), "Normal", IF(I26 < INDEX('Referência'!$D$2:$D$21, MATCH(F26&E26, 'Referência'!$A$2:$A$21, 0)), "Sobrepeso", "Obesidade"))), "")}
A27: 23 | B27: ='Secret. Escolar'!$B$28 | C27: ='Secret. Escolar'!$C$28 | I27: =IFERROR(G27/(H27*H27), "") | J27: {=IFERROR(IF(I27 < INDEX('Referência'!$B$2:$B$21, MATCH(F27&E27, 'Referência'!$A$2:$A$21, 0)), "Abaixo do peso", IF(I27 < INDEX('Referência'!$C$2:$C$21, MATCH(F27&E27, 'Referência'!$A$2:$A$21, 0)), "Normal", IF(I27 < INDEX('Referência'!$D$2:$D$21, MATCH(F27&E27, 'Referência'!$A$2:$A$21, 0)), "Sobrepeso", "Obesidade"))), "")}
A28: 24 | B28: ='Secret. Escolar'!$B$29 | C28: ='Secret. Escolar'!$C$29 | I28: =IFERROR(G28/(H28*H28), "") | J28: {=IFERROR(IF(I28 < INDEX('Referência'!$B$2:$B$21, MATCH(F28&E28, 'Referência'!$A$2:$A$21, 0)), "Abaixo do peso", IF(I28 < INDEX('Referência'!$C$2:$C$21, MATCH(F28&E28, 'Referência'!$A$2:$A$21, 0)), "Normal", IF(I28 < INDEX('Referência'!$D$2:$D$21, MATCH(F28&E28, 'Referência'!$A$2:$A$21, 0)), "Sobrepeso", "Obesidade"))), "")}
A29: 25 | B29: ='Secret. Escolar'!$B$30 | C29: ='Secret. Escolar'!$C$30 | I29: =IFERROR(G29/(H29*H29), "") | J29: {=IFERROR(IF(I29 < INDEX('Referência'!$B$2:$B$21, MATCH(F29&E29, 'Referência'!$A$2:$A$21, 0)), "Abaixo do peso", IF(I29 < INDEX('Referência'!$C$2:$C$21, MATCH(F29&E29, 'Referência'!$A$2:$A$21, 0)), "Normal", IF(I29 < INDEX('Referência'!$D$2:$D$21, MATCH(F29&E29, 'Referência'!$A$2:$A$21, 0)), "Sobrepeso", "Obesidade"))), "")}
A30: 26 | B30: ='Secret. Escolar'!$B$31 | C30: ='Secret. Escolar'!$C$31 | I30: =IFERROR(G30/(H30*H30), "") | J30: {=IFERROR(IF(I30 < INDEX('Referência'!$B$2:$B$21, MATCH(F30&E30, 'Referência'!$A$2:$A$21, 0)), "Abaixo do peso", IF(I30 < INDEX('Referência'!$C$2:$C$21, MATCH(F30&E30, 'Referência'!$A$2:$A$21, 0)), "Normal", IF(I30 < INDEX('Referência'!$D$2:$D$21, MATCH(F30&E30, 'Referência'!$A$2:$A$21, 0)), "Sobrepeso", "Obesidade"))), "")}
A31: 27 | B31: ='Secret. Escolar'!$B$32 | C31: ='Secret. Escolar'!$C$32 | I31: =IFERROR(G31/(H31*H31), "") | J31: {=IFERROR(IF(I31 < INDEX('Referência'!$B$2:$B$21, MATCH(F31&E31, 'Referência'!$A$2:$A$21, 0)), "Abaixo do peso", IF(I31 < INDEX('Referência'!$C$2:$C$21, MATCH(F31&E31, 'Referência'!$A$2:$A$21, 0)), "Normal", IF(I31 < INDEX('Referência'!$D$2:$D$21, MATCH(F31&E31, 'Referência'!$A$2:$A$21, 0)), "Sobrepeso", "Obesidade"))), "")}
A32: 28 | B32: ='Secret. Escolar'!$B$33 | C32: ='Secret. Escolar'!$C$33 | I32: =IFERROR(G32/(H32*H32), "") | J32: {=IFERROR(IF(I32 < INDEX('Referência'!$B$2:$B$21, MATCH(F32&E32, 'Referência'!$A$2:$A$21, 0)), "Abaixo do peso", IF(I32 < INDEX('Referência'!$C$2:$C$21, MATCH(F32&E32, 'Referência'!$A$2:$A$21, 0)), "Normal", IF(I32 < INDEX('Referência'!$D$2:$D$21, MATCH(F32&E32, 'Referência'!$A$2:$A$21, 0)), "Sobrepeso", "Obesidade"))), "")}
A33: 29 | B33: ='Secret. Escolar'!$B$34 | C33: ='Secret. Escolar'!$C$34 | I33: =IFERROR(G33/(H33*H33), "") | J33: {=IFERROR(IF(I33 < INDEX('Referência'!$B$2:$B$21, MATCH(F33&E33, 'Referência'!$A$2:$A$21, 0)), "Abaixo do peso", IF(I33 < INDEX('Referência'!$C$2:$C$21, MATCH(F33&E33, 'Referência'!$A$2:$A$21, 0)), "Normal", IF(I33 < INDEX('Referência'!$D$2:$D$21, MATCH(F33&E33, 'Referência'!$A$2:$A$21, 0)), "Sobrepeso", "Obesidade"))), "")}
A34: 30 | B34: ='Secret. Escolar'!$B$35 | C34: ='Secret. Escolar'!$C$35 | I34: =IFERROR(G34/(H34*H34), "") | J34: {=IFERROR(IF(I34 < INDEX('Referência'!$B$2:$B$21, MATCH(F34&E34, 'Referência'!$A$2:$A$21, 0)), "Abaixo do peso", IF(I34 < INDEX('Referência'!$C$2:$C$21, MATCH(F34&E34, 'Referência'!$A$2:$A$21, 0)), "Normal", IF(I34 < INDEX('Referência'!$D$2:$D$21, MATCH(F34&E34, 'Referência'!$A$2:$A$21, 0)), "Sobrepeso", "Obesidade"))), "")}
A35: 31 | B35: ='Secret. Escolar'!$B$36 | C35: ='Secret. Escolar'!$C$36 | I35: =IFERROR(G35/(H35*H35), "") | J35: {=IFERROR(IF(I35 < INDEX('Referência'!$B$2:$B$21, MATCH(F35&E35, 'Referência'!$A$2:$A$21, 0)), "Abaixo do peso", IF(I35 < INDEX('Referência'!$C$2:$C$21, MATCH(F35&E35, 'Referência'!$A$2:$A$21, 0)), "Normal", IF(I35 < INDEX('Referência'!$D$2:$D$21, MATCH(F35&E35, 'Referência'!$A$2:$A$21, 0)), "Sobrepeso", "Obesidade"))), "")}
A36: 32 | B36: ='Secret. Escolar'!$B$37 | C36: ='Secret. Escolar'!$C$37 | I36: =IFERROR(G36/(H36*H36), "") | J36: {=IFERROR(IF(I36 < INDEX('Referência'!$B$2:$B$21, MATCH(F36&E36, 'Referência'!$A$2:$A$21, 0)), "Abaixo do peso", IF(I36 < INDEX('Referência'!$C$2:$C$21, MATCH(F36&E36, 'Referência'!$A$2:$A$21, 0)), "Normal", IF(I36 < INDEX('Referência'!$D$2:$D$21, MATCH(F36&E36, 'Referência'!$A$2:$A$21, 0)), "Sobrepeso", "Obesidade"))), "")}
A37: 33 | B37: ='Secret. Escolar'!$B$38 | C37: ='Secret. Escolar'!$C$38 | I37: =IFERROR(G37/(H37*H37), "") | J37: {=IFERROR(IF(I37 < INDEX('Referência'!$B$2:$B$21, MATCH(F37&E37, 'Referência'!$A$2:$A$21, 0)), "Abaixo do peso", IF(I37 < INDEX('Referência'!$C$2:$C$21, MATCH(F37&E37, 'Referência'!$A$2:$A$21, 0)), "Normal", IF(I37 < INDEX('Referência'!$D$2:$D$21, MATCH(F37&E37, 'Referência'!$A$2:$A$21, 0)), "Sobrepeso", "Obesidade"))), "")}
A38: 34 | B38: ='Secret. Escolar'!$B$39 | C38: ='Secret. Escolar'!$C$39 | I38: =IFERROR(G38/(H38*H38), "") | J38: {=IFERROR(IF(I38 < INDEX('Referência'!$B$2:$B$21, MATCH(F38&E38, 'Referência'!$A$2:$A$21, 0)), "Abaixo do peso", IF(I38 < INDEX('Referência'!$C$2:$C$21, MATCH(F38&E38, 'Referência'!$A$2:$A$21, 0)), "Normal", IF(I38 < INDEX('Referência'!$D$2:$D$21, MATCH(F38&E38, 'Referência'!$A$2:$A$21, 0)), "Sobrepeso", "Obesidade"))), "")}
A39: 35 | B39: ='Secret. Escolar'!$B$40 | C39: ='Secret. Escolar'!$C$40 | I39: =IFERROR(G39/(H39*H39), "") | J39: {=IFERROR(IF(I39 < INDEX('Referência'!$B$2:$B$21, MATCH(F39&E39, 'Referência'!$A$2:$A$21, 0)), "Abaixo do peso", IF(I39 < INDEX('Referência'!$C$2:$C$21, MATCH(F39&E39, 'Referência'!$A$2:$A$21, 0)), "Normal", IF(I39 < INDEX('Referência'!$D$2:$D$21, MATCH(F39&E39, 'Referência'!$A$2:$A$21, 0)), "Sobrepeso", "Obesidade"))), "")}
A40: 36 | B40: ='Secret. Escolar'!$B$41 | C40: ='Secret. Escolar'!$C$41 | I40: =IFERROR(G40/(H40*H40), "") | J40: {=IFERROR(IF(I40 < INDEX('Referência'!$B$2:$B$21, MATCH(F40&E40, 'Referência'!$A$2:$A$21, 0)), "Abaixo do peso", IF(I40 < INDEX('Referência'!$C$2:$C$21, MATCH(F40&E40, 'Referência'!$A$2:$A$21, 0)), "Normal", IF(I40 < INDEX('Referência'!$D$2:$D$21, MATCH(F40&E40, 'Referência'!$A$2:$A$21, 0)), "Sobrepeso", "Obesidade"))), "")}
...

Sheet Avaliação 1º Semestre.
A1: ="Componente Curricular: "&Capa!J38&"" -> Componente Curricular: Educaçao Física | D1: ="Ano: "&Capa!F30&" Turma: "&Capa!N30&" Turno: "&Capa!F32&" Ano Letivo: "&Capa!O32&" 1º Semestre"&" " -> Ano: 2° Turma: D Turno: Vespertino Ano Letivo: 2026 1º Semestre
D2: ="Professor(a): "&Capa!G35 -> Professor(a): ITAMAR VIEIRA NUNES
A3: Nº DO ALUNO | B3: Nome dos alunos | C3: AULAS DADAS | D3: AVALIAÇÕES CONTÍNUAS e PROCESSUAIS | L3: TOTAL DE FALTA | M3: % Faltas Semestral
C4: =SUM('Reg. Aulas 1º Bim'!C37,'Reg. Aulas 2º Bim'!C37) -> 20 | D4: VALORES E ATITUDES
C5: Movimentções | D5: Relacionamento | E5: Assiduidade | F5: Pontualidade | G5: Expressividade | H5: Equilibrio | I5: Coordenação | J5: Aula Prática | K5: Aula Teórica
A6: 1 | B6: ='Secret. Escolar'!$B$6 -> Adriana Sofia Gonzalez Torres | C6: ='Secret. Escolar'!$C$6 | L6: =SUM('Frequência 1º Bim'!AI6,'Frequência 2º Bim'!AI6) -> 0 | M6: =IFERROR((C4-L6)*1/C4, "") -> 1
A7: 2 | B7: ='Secret. Escolar'!$B$7 -> Alyson Lucas de Sousa Alencar | C7: ='Secret. Escolar'!$C$7 | L7: =SUM('Frequência 1º Bim'!AI7,'Frequência 2º Bim'!AI7) -> 0 | M7: =IFERROR((C5-L7)*1/C5, "")
A8: 3 | B8: ='Secret. Escolar'!$B$8 -> Ana Clara Silva Zanolim | C8: ='Secret. Escolar'!$C$8 | L8: =SUM('Frequência 1º Bim'!AI8,'Frequência 2º Bim'!AI8) -> 0 | M8: =IFERROR((C6-L8)*1/C6, "")
A9: 4 | B9: ='Secret. Escolar'!$B$9 -> Antônio Alves Pereira de Souza | C9: ='Secret. Escolar'!$C$9 | L9: =SUM('Frequência 1º Bim'!AI9,'Frequência 2º Bim'!AI9) -> 1 | M9: =IFERROR((C7-L9)*1/C7, "")
A10: 5 | B10: ='Secret. Escolar'!$B$10 -> Cecília Resende dos Santos | C10: ='Secret. Escolar'!$C$10 | L10: =SUM('Frequência 1º Bim'!AI10,'Frequência 2º Bim'!AI10) -> 0 | M10: =IFERROR((C8-L10)*1/C8, "")
A11: 6 | B11: ='Secret. Escolar'!$B$11 -> Emanuelly Vale da Silva | C11: ='Secret. Escolar'!$C$11 | L11: =SUM('Frequência 1º Bim'!AI11,'Frequência 2º Bim'!AI11) -> 0 | M11: =IFERROR((C9-L11)*1/C9, "")
A12: 7 | B12: ='Secret. Escolar'!$B$12 -> Glloria Vitorya Moreira do Vale | C12: ='Secret. Escolar'!$C$12 | L12: =SUM('Frequência 1º Bim'!AI12,'Frequência 2º Bim'!AI12) -> 0 | M12: =IFERROR((C10-L12)*1/C10, "")
A13: 8 | B13: ='Secret. Escolar'!$B$13 -> Izabelly Vitória Pereira Muniz | C13: ='Secret. Escolar'!$C$13 | L13: =SUM('Frequência 1º Bim'!AI13,'Frequência 2º Bim'!AI13) -> 1 | M13: =IFERROR((C11-L13)*1/C11, "")
A14: 9 | B14: ='Secret. Escolar'!$B$14 -> Kaleu Carneiro Mesquita Tavares | C14: ='Secret. Escolar'!$C$14 | L14: =SUM('Frequência 1º Bim'!AI14,'Frequência 2º Bim'!AI14) -> 0 | M14: =IFERROR((C12-L14)*1/C12, "")
A15: 10 | B15: ='Secret. Escolar'!$B$15 -> Lelimar Sofia Reyes Febres | C15: ='Secret. Escolar'!$C$15 | L15: =SUM('Frequência 1º Bim'!AI15,'Frequência 2º Bim'!AI15) -> 0 | M15: =IFERROR((C13-L15)*1/C13, "")
A16: 11 | B16: ='Secret. Escolar'!$B$16 -> Luiz Gustavo Rodrigues Carneiro | C16: ='Secret. Escolar'!$C$16 | L16: =SUM('Frequência 1º Bim'!AI16,'Frequência 2º Bim'!AI16) -> 0 | M16: =IFERROR((C14-L16)*1/C14, "")
A17: 12 | B17: ='Secret. Escolar'!$B$17 -> Luiz Otávio Santos de Sousa | C17: ='Secret. Escolar'!$C$17 | L17: =SUM('Frequência 1º Bim'!AI17,'Frequência 2º Bim'!AI17) -> 0 | M17: =IFERROR((C15-L17)*1/C15, "")
A18: 13 | B18: ='Secret. Escolar'!$B$18 -> Maria Valentina de Souza | C18: ='Secret. Escolar'!$C$18 | L18: =SUM('Frequência 1º Bim'!AI18,'Frequência 2º Bim'!AI18) -> 0 | M18: =IFERROR((C16-L18)*1/C16, "")
A19: 14 | B19: ='Secret. Escolar'!$B$19 -> Maysa Barros Caitano dos Santos | C19: ='Secret. Escolar'!$C$19 | L19: =SUM('Frequência 1º Bim'!AI19,'Frequência 2º Bim'!AI19) -> 0 | M19: =IFERROR((C17-L19)*1/C17, "")
A20: 15 | B20: ='Secret. Escolar'!$B$20 -> Melissa Oliveira Magalhães | C20: ='Secret. Escolar'!$C$20 | L20: =SUM('Frequência 1º Bim'!AI20,'Frequência 2º Bim'!AI20) -> 0 | M20: =IFERROR((C18-L20)*1/C18, "")
A21: 16 | B21: ='Secret. Escolar'!$B$21 -> Neilson de Oliveira Carneiro | C21: ='Secret. Escolar'!$C$21 | L21: =SUM('Frequência 1º Bim'!AI21,'Frequência 2º Bim'!AI21) -> 0 | M21: =IFERROR((C19-L21)*1/C19, "")
A22: 17 | B22: ='Secret. Escolar'!$B$22 -> Sarah Gabrielle Coelho Lopes | C22: ='Secret. Escolar'!$C$22 | L22: =SUM('Frequência 1º Bim'!AI22,'Frequência 2º Bim'!AI22) -> 0 | M22: =IFERROR((C20-L22)*1/C20, "")
A23: 18 | B23: ='Secret. Escolar'!$B$23 -> Sophia Pereira de Oliveira | C23: ='Secret. Escolar'!$C$23 | L23: =SUM('Frequência 1º Bim'!AI23,'Frequência 2º Bim'!AI23) -> 0 | M23: =IFERROR((C21-L23)*1/C21, "")
A24: 19 | B24: ='Secret. Escolar'!$B$24 -> Wuilmer Adrian Ramos Salazar | C24: ='Secret. Escolar'!$C$24 | L24: =SUM('Frequência 1º Bim'!AI24,'Frequência 2º Bim'!AI24) -> 0 | M24: =IFERROR((C22-L24)*1/C22, "")
A25: 20 | B25: ='Secret. Escolar'!$B$25 | C25: ='Secret. Escolar'!$C$25 | L25: =SUM('Frequência 1º Bim'!AI25,'Frequência 2º Bim'!AI25) -> 0 | M25: =IFERROR((C23-L25)*1/C23, "")
A26: 21 | B26: ='Secret. Escolar'!$B$26 | C26: ='Secret. Escolar'!$C$26 | L26: =SUM('Frequência 1º Bim'!AI26,'Frequência 2º Bim'!AI26) -> 0 | M26: =IFERROR((C24-L26)*1/C24, "")
A27: 22 | B27: ='Secret. Escolar'!$B$27 | C27: ='Secret. Escolar'!$C$27 | L27: =SUM('Frequência 1º Bim'!AI27,'Frequência 2º Bim'!AI27) -> 0 | M27: =IFERROR((C25-L27)*1/C25, "")
A28: 23 | B28: ='Secret. Escolar'!$B$28 | C28: ='Secret. Escolar'!$C$28 | L28: =SUM('Frequência 1º Bim'!AI28,'Frequência 2º Bim'!AI28) -> 0 | M28: =IFERROR((C26-L28)*1/C26, "")
A29: 24 | B29: ='Secret. Escolar'!$B$29 | C29: ='Secret. Escolar'!$C$29 | L29: =SUM('Frequência 1º Bim'!AI29,'Frequência 2º Bim'!AI29) -> 0 | M29: =IFERROR((C27-L29)*1/C27, "")
A30: 25 | B30: ='Secret. Escolar'!$B$30 | C30: ='Secret. Escolar'!$C$30 | L30: =SUM('Frequência 1º Bim'!AI30,'Frequência 2º Bim'!AI30) -> 0 | M30: =IFERROR((C28-L30)*1/C28, "")
A31: 26 | B31: ='Secret. Escolar'!$B$31 | C31: ='Secret. Escolar'!$C$31 | L31: =SUM('Frequência 1º Bim'!AI31,'Frequência 2º Bim'!AI31) -> 0 | M31: =IFERROR((C29-L31)*1/C29, "")
A32: 27 | B32: ='Secret. Escolar'!$B$32 | C32: ='Secret. Escolar'!$C$32 | L32: =SUM('Frequência 1º Bim'!AI32,'Frequência 2º Bim'!AI32) -> 0 | M32: =IFERROR((C30-L32)*1/C30, "")
A33: 28 | B33: ='Secret. Escolar'!$B$33 | C33: ='Secret. Escolar'!$C$33 | L33: =SUM('Frequência 1º Bim'!AI33,'Frequência 2º Bim'!AI33) -> 0 | M33: =IFERROR((C31-L33)*1/C31, "")
A34: 29 | B34: ='Secret. Escolar'!$B$34 | C34: ='Secret. Escolar'!$C$34 | L34: =SUM('Frequência 1º Bim'!AI34,'Frequência 2º Bim'!AI34) -> 0 | M34: =IFERROR((C32-L34)*1/C32, "")
A35: 30 | B35: ='Secret. Escolar'!$B$35 | C35: ='Secret. Escolar'!$C$35 | L35: =SUM('Frequência 1º Bim'!AI35,'Frequência 2º Bim'!AI35) -> 0 | M35: =IFERROR((C33-L35)*1/C33, "")
A36: 31 | B36: ='Secret. Escolar'!$B$36 | C36: ='Secret. Escolar'!$C$36 | L36: =SUM('Frequência 1º Bim'!AI36,'Frequência 2º Bim'!AI36) -> 0 | M36: =IFERROR((C34-L36)*1/C34, "")
A37: 32 | B37: ='Secret. Escolar'!$B$37 | C37: ='Secret. Escolar'!$C$37 | L37: =SUM('Frequência 1º Bim'!AI37,'Frequência 2º Bim'!AI37) -> 0 | M37: =IFERROR((C35-L37)*1/C35, "")
A38: 33 | B38: ='Secret. Escolar'!$B$38 | C38: ='Secret. Escolar'!$C$38 | L38: =SUM('Frequência 1º Bim'!AI38,'Frequência 2º Bim'!AI38) -> 0 | M38: =IFERROR((C36-L38)*1/C36, "")
A39: 34 | B39: ='Secret. Escolar'!$B$39 | C39: ='Secret. Escolar'!$C$39 | L39: =SUM('Frequência 1º Bim'!AI39,'Frequência 2º Bim'!AI39) -> 0 | M39: =IFERROR((C37-L39)*1/C37, "")
A40: 35 | B40: ='Secret. Escolar'!$B$40 | C40: ='Secret. Escolar'!$C$40 | L40: =SUM('Frequência 1º Bim'!AI40,'Frequência 2º Bim'!AI40) -> 0 | M40: =IFERROR((C38-L40)*1/C38, "")
...

Sheet Frequência 3º Bim
A1: ="Componente Curricular: "&Capa!J38&"" -> Componente Curricular: Educaçao Física | D1: ="Ano: "&Capa!F30&" Turma: "&Capa!N30&" Turno: "&Capa!F32&" Ano Letivo: "&Capa!O32&" 3º Bimestre"&" Professor(a): "&Capa!G35 -> Ano: 2° Turma: D Turno: Vespertino Ano Letivo: 2026 3º Bimestre Professor(a): ITAMAR VIEIRA NUNES
A3: Nº ALUNO | B3: ="Aulas Dadas: "&COUNTA(E5:AH5) -> Aulas Dadas: 0 | C3: Movimentções | D3: Registro de Frequência
D4: AULAS DADAS | E4: 1 | F4: 2 | G4: 3 | H4: 4 | I4: 5 | J4: 6 | K4: 7 | L4: 8 | M4: 9 | N4: 10 | O4: 11 | P4: 12 | Q4: 13 | R4: 14 | S4: 15 | T4: 16 | U4: 17 | V4: 18 | W4: 19 | X4: 20 | Y4: 21 | Z4: 22 | AA4: 23 | AB4: 24 | AC4: 25 | AD4: 26 | AE4: 27 | AF4: 28 | AG4: 29 | AH4: 30 | AI4: Total de falta
B5: Nome dos alunos
A6: 1 | B6: ='Secret. Escolar'!$B$6 -> Adriana Sofia Gonzalez Torres | C6: ='Secret. Escolar'!$C$6 | D6: 1 | AI6: =COUNTIF(E6:AH6,"f") -> 0
A7: 2 | B7: ='Secret. Escolar'!$B$7 -> Alyson Lucas de Sousa Alencar | C7: ='Secret. Escolar'!$C$7 | D7: 2 | AI7: =COUNTIF(E7:AH7,"f") -> 0
A8: 3 | B8: ='Secret. Escolar'!$B$8 -> Ana Clara Silva Zanolim | C8: ='Secret. Escolar'!$C$8 | D8: 3 | AI8: =COUNTIF(E8:AH8,"f") -> 0
A9: 4 | B9: ='Secret. Escolar'!$B$9 -> Antônio Alves Pereira de Souza | C9: ='Secret. Escolar'!$C$9 | D9: 4 | AI9: =COUNTIF(E9:AH9,"f") -> 0
A10: 5 | B10: ='Secret. Escolar'!$B$10 -> Cecília Resende dos Santos | C10: ='Secret. Escolar'!$C$10 | D10: 5 | AI10: =COUNTIF(E10:AH10,"f") -> 0
A11: 6 | B11: ='Secret. Escolar'!$B$11 -> Emanuelly Vale da Silva | C11: ='Secret. Escolar'!$C$11 | D11: 6 | AI11: =COUNTIF(E11:AH11,"f") -> 0
A12: 7 | B12: ='Secret. Escolar'!$B$12 -> Glloria Vitorya Moreira do Vale | C12: ='Secret. Escolar'!$C$12 | D12: 7 | AI12: =COUNTIF(E12:AH12,"f") -> 0
A13: 8 | B13: ='Secret. Escolar'!$B$13 -> Izabelly Vitória Pereira Muniz | C13: ='Secret. Escolar'!$C$13 | D13: 8 | AI13: =COUNTIF(E13:AH13,"f") -> 0
A14: 9 | B14: ='Secret. Escolar'!$B$14 -> Kaleu Carneiro Mesquita Tavares | C14: ='Secret. Escolar'!$C$14 | D14: 9 | AI14: =COUNTIF(E14:AH14,"f") -> 0
A15: 10 | B15: ='Secret. Escolar'!$B$15 -> Lelimar Sofia Reyes Febres | C15: ='Secret. Escolar'!$C$15 | D15: 10 | AI15: =COUNTIF(E15:AH15,"f") -> 0
A16: 11 | B16: ='Secret. Escolar'!$B$16 -> Luiz Gustavo Rodrigues Carneiro | C16: ='Secret. Escolar'!$C$16 | D16: 11 | AI16: =COUNTIF(E16:AH16,"f") -> 0
A17: 12 | B17: ='Secret. Escolar'!$B$17 -> Luiz Otávio Santos de Sousa | C17: ='Secret. Escolar'!$C$17 | D17: 12 | AI17: =COUNTIF(E17:AH17,"f") -> 0
A18: 13 | B18: ='Secret. Escolar'!$B$18 -> Maria Valentina de Souza | C18: ='Secret. Escolar'!$C$18 | D18: 13 | AI18: =COUNTIF(E18:AH18,"f") -> 0
A19: 14 | B19: ='Secret. Escolar'!$B$19 -> Maysa Barros Caitano dos Santos | C19: ='Secret. Escolar'!$C$19 | D19: 14 | AI19: =COUNTIF(E19:AH19,"f") -> 0
A20: 15 | B20: ='Secret. Escolar'!$B$20 -> Melissa Oliveira Magalhães | C20: ='Secret. Escolar'!$C$20 | D20: 15 | AI20: =COUNTIF(E20:AH20,"f") -> 0
A21: 16 | B21: ='Secret. Escolar'!$B$21 -> Neilson de Oliveira Carneiro | C21: ='Secret. Escolar'!$C$21 | D21: 16 | AI21: =COUNTIF(E21:AH21,"f") -> 0
A22: 17 | B22: ='Secret. Escolar'!$B$22 -> Sarah Gabrielle Coelho Lopes | C22: ='Secret. Escolar'!$C$22 | D22: 17 | AI22: =COUNTIF(E22:AH22,"f") -> 0
A23: 18 | B23: ='Secret. Escolar'!$B$23 -> Sophia Pereira de Oliveira | C23: ='Secret. Escolar'!$C$23 | D23: 18 | AI23: =COUNTIF(E23:AH23,"f") -> 0
A24: 19 | B24: ='Secret. Escolar'!$B$24 -> Wuilmer Adrian Ramos Salazar | C24: ='Secret. Escolar'!$C$24 | D24: 19 | AI24: =COUNTIF(E24:AH24,"f") -> 0
A25: 20 | B25: ='Secret. Escolar'!$B$25 | C25: ='Secret. Escolar'!$C$25 | D25: 20 | AI25: =COUNTIF(E25:AH25,"f") -> 0
A26: 21 | B26: ='Secret. Escolar'!$B$26 | C26: ='Secret. Escolar'!$C$26 | D26: 21 | AI26: =COUNTIF(E26:AH26,"f") -> 0
A27: 22 | B27: ='Secret. Escolar'!$B$27 | C27: ='Secret. Escolar'!$C$27 | D27: 22 | AI27: =COUNTIF(E27:AH27,"f") -> 0
A28: 23 | B28: ='Secret. Escolar'!$B$28 | C28: ='Secret. Escolar'!$C$28 | D28: 23 | AI28: =COUNTIF(E28:AH28,"f") -> 0
A29: 24 | B29: ='Secret. Escolar'!$B$29 | C29: ='Secret. Escolar'!$C$29 | D29: 24 | AI29: =COUNTIF(E29:AH29,"f") -> 0
A30: 25 | B30: ='Secret. Escolar'!$B$30 | C30: ='Secret. Escolar'!$C$30 | D30: 25 | AI30: =COUNTIF(E30:AH30,"f") -> 0
A31: 26 | B31: ='Secret. Escolar'!$B$31 | C31: ='Secret. Escolar'!$C$31 | D31: 26 | AI31: =COUNTIF(E31:AH31,"f") -> 0
